ERROR:root:

 2022-08-01 12:02:14.482419, Report Failed!
Traceback (most recent call last):
  File "D:\GitHub_Repos\CU_Collect\CU_Collect\venv\lib\site-packages\pandas\core\indexes\base.py", line 3621, in get_loc
    return self._engine.get_loc(casted_key)
  File "pandas\_libs\index.pyx", line 136, in pandas._libs.index.IndexEngine.get_loc
  File "pandas\_libs\index.pyx", line 163, in pandas._libs.index.IndexEngine.get_loc
  File "pandas\_libs\hashtable_class_helper.pxi", line 5198, in pandas._libs.hashtable.PyObjectHashTable.get_item
  File "pandas\_libs\hashtable_class_helper.pxi", line 5206, in pandas._libs.hashtable.PyObjectHashTable.get_item
KeyError: 'date'

The above exception was the direct cause of the following exception:

Traceback (most recent call last):
  File "D:/GitHub_Repos/OnePoint_Management/OnePoint_Management/OnePoint_Followup_Report/main.py", line 12, in Main
    filterFollow_Ups(df)
  File "D:\GitHub_Repos\OnePoint_Management\OnePoint_Management\OnePoint_Followup_Report\utils.py", line 38, in filterFollow_Ups
    df_last_week = df[(df['date'] > '2019-12-01')]
  File "D:\GitHub_Repos\CU_Collect\CU_Collect\venv\lib\site-packages\pandas\core\frame.py", line 3505, in __getitem__
    indexer = self.columns.get_loc(key)
  File "D:\GitHub_Repos\CU_Collect\CU_Collect\venv\lib\site-packages\pandas\core\indexes\base.py", line 3623, in get_loc
    raise KeyError(key) from err
KeyError: 'date'
